[2024-02-15T17:36:39.750+0900] {taskinstance.py:1956} INFO - Dependencies all met for dep_context=non-requeueable deps ti=<TaskInstance: CollectCommunity.community_Collect manual__2024-02-15T08:36:03.443244+00:00 [queued]>
[2024-02-15T17:36:39.757+0900] {taskinstance.py:1956} INFO - Dependencies all met for dep_context=requeueable deps ti=<TaskInstance: CollectCommunity.community_Collect manual__2024-02-15T08:36:03.443244+00:00 [queued]>
[2024-02-15T17:36:39.757+0900] {taskinstance.py:2170} INFO - Starting attempt 1 of 1
[2024-02-15T17:36:39.929+0900] {taskinstance.py:2191} INFO - Executing <Task(PythonOperator): community_Collect> on 2024-02-15 08:36:03.443244+00:00
[2024-02-15T17:36:39.935+0900] {standard_task_runner.py:60} INFO - Started process 6285 to run task
[2024-02-15T17:36:39.940+0900] {standard_task_runner.py:87} INFO - Running: ['airflow', 'tasks', 'run', 'CollectCommunity', 'community_Collect', 'manual__2024-02-15T08:36:03.443244+00:00', '--job-id', '6', '--raw', '--subdir', 'DAGS_FOLDER/Community_Collect.py', '--cfg-path', '/tmp/tmpumd0r3z7']
[2024-02-15T17:36:39.942+0900] {standard_task_runner.py:88} INFO - Job 6: Subtask community_Collect
[2024-02-15T17:36:39.983+0900] {task_command.py:423} INFO - Running <TaskInstance: CollectCommunity.community_Collect manual__2024-02-15T08:36:03.443244+00:00 [running]> on host ip-172-31-11-88.ap-northeast-2.compute.internal
[2024-02-15T17:36:40.045+0900] {taskinstance.py:2480} INFO - Exporting env vars: AIRFLOW_CTX_DAG_OWNER='airflow' AIRFLOW_CTX_DAG_ID='CollectCommunity' AIRFLOW_CTX_TASK_ID='community_Collect' AIRFLOW_CTX_EXECUTION_DATE='2024-02-15T08:36:03.443244+00:00' AIRFLOW_CTX_TRY_NUMBER='1' AIRFLOW_CTX_DAG_RUN_ID='manual__2024-02-15T08:36:03.443244+00:00'
[2024-02-15T17:36:44.711+0900] {taskinstance.py:2698} ERROR - Task failed with exception
Traceback (most recent call last):
  File "/usr/local/lib/python3.10/dist-packages/airflow/models/taskinstance.py", line 433, in _execute_task
    result = execute_callable(context=context, **execute_callable_kwargs)
  File "/usr/local/lib/python3.10/dist-packages/airflow/operators/python.py", line 199, in execute
    return_value = self.execute_callable()
  File "/usr/local/lib/python3.10/dist-packages/airflow/operators/python.py", line 216, in execute_callable
    return self.python_callable(*self.op_args, **self.op_kwargs)
  File "/home/ubuntu/airflow/dags/Community_Collect.py", line 88, in community_Collect
    df.to_csv(f"/home/ubuntu/community_list/{today}_community_URL.csv", index = None)
NameError: name 'df' is not defined
[2024-02-15T17:36:44.717+0900] {taskinstance.py:1138} INFO - Marking task as FAILED. dag_id=CollectCommunity, task_id=community_Collect, execution_date=20240215T083603, start_date=20240215T083639, end_date=20240215T083644
[2024-02-15T17:36:44.732+0900] {standard_task_runner.py:107} ERROR - Failed to execute job 6 for task community_Collect (name 'df' is not defined; 6285)
[2024-02-15T17:36:44.773+0900] {local_task_job_runner.py:234} INFO - Task exited with return code 1
[2024-02-15T17:36:44.792+0900] {taskinstance.py:3280} INFO - 0 downstream tasks scheduled from follow-on schedule check
